2021-09-03 20:15:42,067 INFO    MainThread:9040 [internal.py:wandb_internal():86] W&B internal server running at pid: 9040, started at: 2021-09-03 20:15:42.042387
2021-09-03 20:15:42,122 DEBUG   SenderThread:9040 [sender.py:send():182] send: header
2021-09-03 20:15:42,123 INFO    WriterThread:9040 [datastore.py:open_for_write():77] open: C:\Users\Bahar\sources\repo\Advanced_Python\MachineLearning\wandb\run-20210903_201533-2kg3mrm3\run-2kg3mrm3.wandb
2021-09-03 20:15:42,125 DEBUG   HandlerThread:9040 [handler.py:handle_request():126] handle_request: check_version
2021-09-03 20:15:42,129 DEBUG   SenderThread:9040 [sender.py:send_request():196] send_request: check_version
2021-09-03 20:15:42,975 DEBUG   SenderThread:9040 [sender.py:send():182] send: run
2021-09-03 20:15:45,048 ERROR   SenderThread:9040 [internal_api.py:execute():133] 403 response executing GraphQL.
2021-09-03 20:15:45,049 ERROR   SenderThread:9040 [internal_api.py:execute():134] <!DOCTYPE html>
<html lang=en>
  <meta charset=utf-8>
  <meta name=viewport content="initial-scale=1, minimum-scale=1, width=device-width">
  <title>Error 403 (Forbidden)!!1</title>
  <style>
    *{margin:0;padding:0}html,code{font:15px/22px arial,sans-serif}html{background:#fff;color:#222;padding:15px}body{margin:7% auto 0;max-width:390px;min-height:180px;padding:30px 0 15px}* > body{background:url(//www.google.com/images/errors/robot.png) 100% 5px no-repeat;padding-right:205px}p{margin:11px 0 22px;overflow:hidden}ins{color:#777;text-decoration:none}a img{border:0}@media screen and (max-width:772px){body{background:none;margin-top:0;max-width:none;padding-right:0}}#logo{background:url(//www.google.com/images/branding/googlelogo/1x/googlelogo_color_150x54dp.png) no-repeat;margin-left:-5px}@media only screen and (min-resolution:192dpi){#logo{background:url(//www.google.com/images/branding/googlelogo/2x/googlelogo_color_150x54dp.png) no-repeat 0% 0%/100% 100%;-moz-border-image:url(//www.google.com/images/branding/googlelogo/2x/googlelogo_color_150x54dp.png) 0}}@media only screen and (-webkit-min-device-pixel-ratio:2){#logo{background:url(//www.google.com/images/branding/googlelogo/2x/googlelogo_color_150x54dp.png) no-repeat;-webkit-background-size:100% 100%}}#logo{display:inline-block;height:54px;width:150px}
  </style>
  <a href=//www.google.com/><span id=logo aria-label=Google></span></a>
  <p><b>403.</b> <ins>That’s an error.</ins>
  <p>Your client does not have permission to get URL <code>/graphql</code> from this server.  <ins>That’s all we know.</ins>

2021-09-03 20:15:45,171 INFO    WriterThread:9040 [datastore.py:close():281] close: C:\Users\Bahar\sources\repo\Advanced_Python\MachineLearning\wandb\run-20210903_201533-2kg3mrm3\run-2kg3mrm3.wandb
2021-09-03 20:15:45,173 INFO    HandlerThread:9040 [handler.py:finish():683] shutting down handler
2021-09-03 20:15:45,176 ERROR   MainThread:9040 [internal.py:wandb_internal():157] Thread SenderThread:
Traceback (most recent call last):
  File "C:\Users\Bahar\AppData\Roaming\Python\Python39\site-packages\wandb\sdk\lib\retry.py", line 102, in __call__
    result = self._call_fn(*args, **kwargs)
  File "C:\Users\Bahar\AppData\Roaming\Python\Python39\site-packages\wandb\sdk\internal\internal_api.py", line 136, in execute
    six.reraise(*sys.exc_info())
  File "C:\Users\Bahar\AppData\Roaming\Python\Python39\site-packages\six.py", line 719, in reraise
    raise value
  File "C:\Users\Bahar\AppData\Roaming\Python\Python39\site-packages\wandb\sdk\internal\internal_api.py", line 130, in execute
    return self.client.execute(*args, **kwargs)
  File "C:\Users\Bahar\AppData\Roaming\Python\Python39\site-packages\wandb\vendor\gql-0.2.0\gql\client.py", line 52, in execute
    result = self._get_result(document, *args, **kwargs)
  File "C:\Users\Bahar\AppData\Roaming\Python\Python39\site-packages\wandb\vendor\gql-0.2.0\gql\client.py", line 60, in _get_result
    return self.transport.execute(document, *args, **kwargs)
  File "C:\Users\Bahar\AppData\Roaming\Python\Python39\site-packages\wandb\vendor\gql-0.2.0\gql\transport\requests.py", line 39, in execute
    request.raise_for_status()
  File "C:\Users\Bahar\AppData\Roaming\Python\Python39\site-packages\requests\models.py", line 953, in raise_for_status
    raise HTTPError(http_error_msg, response=self)
requests.exceptions.HTTPError: 403 Client Error: Forbidden for url: https://api.wandb.ai/graphql

During handling of the above exception, another exception occurred:

Traceback (most recent call last):
  File "C:\Users\Bahar\AppData\Roaming\Python\Python39\site-packages\wandb\apis\normalize.py", line 24, in wrapper
    return func(*args, **kwargs)
  File "C:\Users\Bahar\AppData\Roaming\Python\Python39\site-packages\wandb\sdk\internal\internal_api.py", line 1087, in upsert_run
    response = self.gql(mutation, variable_values=variable_values, **kwargs)
  File "C:\Users\Bahar\AppData\Roaming\Python\Python39\site-packages\wandb\sdk\lib\retry.py", line 118, in __call__
    if not check_retry_fn(e):
  File "C:\Users\Bahar\AppData\Roaming\Python\Python39\site-packages\wandb\util.py", line 809, in no_retry_auth
    raise CommError("Permission denied, ask the project owner to grant you access")
wandb.errors.CommError: Permission denied, ask the project owner to grant you access

During handling of the above exception, another exception occurred:

Traceback (most recent call last):
  File "C:\Users\Bahar\AppData\Roaming\Python\Python39\site-packages\wandb\sdk\internal\internal_util.py", line 52, in run
    self._run()
  File "C:\Users\Bahar\AppData\Roaming\Python\Python39\site-packages\wandb\sdk\internal\internal_util.py", line 102, in _run
    self._process(record)
  File "C:\Users\Bahar\AppData\Roaming\Python\Python39\site-packages\wandb\sdk\internal\internal.py", line 290, in _process
    self._sm.send(record)
  File "C:\Users\Bahar\AppData\Roaming\Python\Python39\site-packages\wandb\sdk\internal\sender.py", line 184, in send
    send_handler(record)
  File "C:\Users\Bahar\AppData\Roaming\Python\Python39\site-packages\wandb\sdk\internal\sender.py", line 623, in send_run
    self._init_run(run, config_value_dict)
  File "C:\Users\Bahar\AppData\Roaming\Python\Python39\site-packages\wandb\sdk\internal\sender.py", line 645, in _init_run
    server_run, inserted = self._api.upsert_run(
  File "C:\Users\Bahar\AppData\Roaming\Python\Python39\site-packages\wandb\apis\normalize.py", line 62, in wrapper
    six.reraise(CommError, CommError(message, err), sys.exc_info()[2])
  File "C:\Users\Bahar\AppData\Roaming\Python\Python39\site-packages\six.py", line 718, in reraise
    raise value.with_traceback(tb)
  File "C:\Users\Bahar\AppData\Roaming\Python\Python39\site-packages\wandb\apis\normalize.py", line 24, in wrapper
    return func(*args, **kwargs)
  File "C:\Users\Bahar\AppData\Roaming\Python\Python39\site-packages\wandb\sdk\internal\internal_api.py", line 1087, in upsert_run
    response = self.gql(mutation, variable_values=variable_values, **kwargs)
  File "C:\Users\Bahar\AppData\Roaming\Python\Python39\site-packages\wandb\sdk\lib\retry.py", line 118, in __call__
    if not check_retry_fn(e):
  File "C:\Users\Bahar\AppData\Roaming\Python\Python39\site-packages\wandb\util.py", line 809, in no_retry_auth
    raise CommError("Permission denied, ask the project owner to grant you access")
wandb.errors.CommError: Permission denied, ask the project owner to grant you access
2021-09-03 20:15:48,436 INFO    MainThread:9040 [internal.py:handle_exit():76] Internal process exited
